{"updated_at": "2011-10-11T13:42:02Z", "repo": "rails", "created_at": "2011-10-11T13:42:02Z", "owner": "rails", "url": "https://api.github.com/repos/rails/rails/issues/comments/2361423", "id": 2361423, "issue_url": "https://api.github.com/repos/rails/rails/issues/3290", "issue_id": 3290, "user": {"repos_url": "https://api.github.com/users/dasch/repos", "type": "User", "html_url": "https://github.com/dasch", "starred_url": "https://api.github.com/users/dasch/starred{/owner}{/repo}", "subscriptions_url": "https://api.github.com/users/dasch/subscriptions", "following_url": "https://api.github.com/users/dasch/following{/other_user}", "gravatar_id": "a9cc05e6a7866e5fa9a7d107b5070174", "organizations_url": "https://api.github.com/users/dasch/orgs", "url": "https://api.github.com/users/dasch", "gists_url": "https://api.github.com/users/dasch/gists{/gist_id}", "avatar_url": "https://0.gravatar.com/avatar/a9cc05e6a7866e5fa9a7d107b5070174?d=https%3A%2F%2Fidenticons.github.com%2Fc6862d63b17d713ee14f3a405d9fde77.png", "id": 6351, "events_url": "https://api.github.com/users/dasch/events{/privacy}", "login": "dasch", "received_events_url": "https://api.github.com/users/dasch/received_events", "followers_url": "https://api.github.com/users/dasch/followers"}, "body": "@dmitriy-kiriyenko catching the exceptions caused by calling a private method is much harder than you'd expect. Take a look at #2736 to see how many hoops you have to run through.\r\n\r\nCan we move this discussion to #2733? I've pushed a new commit which adds back the old method with a \"!\" suffix and a deprecation warning. ", "_id": {"$oid": "52383883bd3543c15101000d"}, "html_url": "https://github.com/rails/rails/pull/3290#issuecomment-2361423"}
